[2025-01-09T16:01:02.199+0000] {local_task_job_runner.py:123} INFO - ::group::Pre task execution logs
[2025-01-09T16:01:02.220+0000] {taskinstance.py:2613} INFO - Dependencies all met for dep_context=non-requeueable deps ti=<TaskInstance: stock_information.stream_data_from_api scheduled__2025-01-09T16:00:00+00:00 [queued]>
[2025-01-09T16:01:02.230+0000] {taskinstance.py:2613} INFO - Dependencies all met for dep_context=requeueable deps ti=<TaskInstance: stock_information.stream_data_from_api scheduled__2025-01-09T16:00:00+00:00 [queued]>
[2025-01-09T16:01:02.232+0000] {taskinstance.py:2866} INFO - Starting attempt 1 of 1
[2025-01-09T16:01:02.250+0000] {taskinstance.py:2889} INFO - Executing <Task(PythonOperator): stream_data_from_api> on 2025-01-09 16:00:00+00:00
[2025-01-09T16:01:02.258+0000] {standard_task_runner.py:72} INFO - Started process 460 to run task
[2025-01-09T16:01:02.262+0000] {standard_task_runner.py:104} INFO - Running: ['airflow', 'tasks', 'run', 'stock_information', 'stream_data_from_api', 'scheduled__2025-01-09T16:00:00+00:00', '--job-id', '48', '--raw', '--subdir', 'DAGS_FOLDER/vnstock_stream.py', '--cfg-path', '/tmp/tmp4nx7e0wn']
[2025-01-09T16:01:02.266+0000] {standard_task_runner.py:105} INFO - Job 48: Subtask stream_data_from_api
[2025-01-09T16:01:02.324+0000] {task_command.py:467} INFO - Running <TaskInstance: stock_information.stream_data_from_api scheduled__2025-01-09T16:00:00+00:00 [running]> on host 453ac4defedc
[2025-01-09T16:01:02.415+0000] {taskinstance.py:3132} INFO - Exporting env vars: AIRFLOW_CTX_DAG_OWNER='TuanDz' AIRFLOW_CTX_DAG_ID='stock_information' AIRFLOW_CTX_TASK_ID='stream_data_from_api' AIRFLOW_CTX_EXECUTION_DATE='2025-01-09T16:00:00+00:00' AIRFLOW_CTX_TRY_NUMBER='1' AIRFLOW_CTX_DAG_RUN_ID='scheduled__2025-01-09T16:00:00+00:00'
[2025-01-09T16:01:02.417+0000] {taskinstance.py:731} INFO - ::endgroup::
[2025-01-09T16:02:02.846+0000] {data_explorer.py:64} WARNING - Thông tin niêm yết & giao dịch sẽ được truy xuất từ TCBS
[2025-01-09T16:03:03.375+0000] {data_explorer.py:64} WARNING - Thông tin niêm yết & giao dịch sẽ được truy xuất từ TCBS
[2025-01-09T16:04:03.998+0000] {data_explorer.py:64} WARNING - Thông tin niêm yết & giao dịch sẽ được truy xuất từ TCBS
[2025-01-09T16:05:04.454+0000] {data_explorer.py:64} WARNING - Thông tin niêm yết & giao dịch sẽ được truy xuất từ TCBS
[2025-01-09T16:06:06.027+0000] {data_explorer.py:64} WARNING - Thông tin niêm yết & giao dịch sẽ được truy xuất từ TCBS
[2025-01-09T16:07:06.470+0000] {data_explorer.py:64} WARNING - Thông tin niêm yết & giao dịch sẽ được truy xuất từ TCBS
[2025-01-09T16:08:06.659+0000] {data_explorer.py:64} WARNING - Thông tin niêm yết & giao dịch sẽ được truy xuất từ TCBS
[2025-01-09T16:09:06.850+0000] {data_explorer.py:64} WARNING - Thông tin niêm yết & giao dịch sẽ được truy xuất từ TCBS
[2025-01-09T16:10:07.068+0000] {data_explorer.py:64} WARNING - Thông tin niêm yết & giao dịch sẽ được truy xuất từ TCBS
[2025-01-09T16:11:07.260+0000] {data_explorer.py:64} WARNING - Thông tin niêm yết & giao dịch sẽ được truy xuất từ TCBS
[2025-01-09T16:12:07.543+0000] {data_explorer.py:64} WARNING - Thông tin niêm yết & giao dịch sẽ được truy xuất từ TCBS
[2025-01-09T16:13:07.873+0000] {data_explorer.py:64} WARNING - Thông tin niêm yết & giao dịch sẽ được truy xuất từ TCBS
[2025-01-09T16:14:08.187+0000] {data_explorer.py:64} WARNING - Thông tin niêm yết & giao dịch sẽ được truy xuất từ TCBS
[2025-01-09T16:15:08.359+0000] {data_explorer.py:64} WARNING - Thông tin niêm yết & giao dịch sẽ được truy xuất từ TCBS
[2025-01-09T16:16:08.551+0000] {data_explorer.py:64} WARNING - Thông tin niêm yết & giao dịch sẽ được truy xuất từ TCBS
[2025-01-09T16:17:08.745+0000] {data_explorer.py:64} WARNING - Thông tin niêm yết & giao dịch sẽ được truy xuất từ TCBS
[2025-01-09T16:18:09.040+0000] {data_explorer.py:64} WARNING - Thông tin niêm yết & giao dịch sẽ được truy xuất từ TCBS
[2025-01-09T16:19:09.375+0000] {data_explorer.py:64} WARNING - Thông tin niêm yết & giao dịch sẽ được truy xuất từ TCBS
[2025-01-09T16:20:10.562+0000] {data_explorer.py:64} WARNING - Thông tin niêm yết & giao dịch sẽ được truy xuất từ TCBS
[2025-01-09T16:21:10.983+0000] {data_explorer.py:64} WARNING - Thông tin niêm yết & giao dịch sẽ được truy xuất từ TCBS
[2025-01-09T16:22:11.167+0000] {data_explorer.py:64} WARNING - Thông tin niêm yết & giao dịch sẽ được truy xuất từ TCBS
[2025-01-09T16:23:11.423+0000] {data_explorer.py:64} WARNING - Thông tin niêm yết & giao dịch sẽ được truy xuất từ TCBS
[2025-01-09T16:24:12.692+0000] {data_explorer.py:64} WARNING - Thông tin niêm yết & giao dịch sẽ được truy xuất từ TCBS
[2025-01-09T16:25:12.876+0000] {data_explorer.py:64} WARNING - Thông tin niêm yết & giao dịch sẽ được truy xuất từ TCBS
[2025-01-09T16:26:13.071+0000] {data_explorer.py:64} WARNING - Thông tin niêm yết & giao dịch sẽ được truy xuất từ TCBS
[2025-01-09T16:27:13.235+0000] {data_explorer.py:64} WARNING - Thông tin niêm yết & giao dịch sẽ được truy xuất từ TCBS
[2025-01-09T16:28:13.739+0000] {data_explorer.py:64} WARNING - Thông tin niêm yết & giao dịch sẽ được truy xuất từ TCBS
[2025-01-09T16:29:14.175+0000] {data_explorer.py:64} WARNING - Thông tin niêm yết & giao dịch sẽ được truy xuất từ TCBS
[2025-01-09T16:30:14.596+0000] {data_explorer.py:64} WARNING - Thông tin niêm yết & giao dịch sẽ được truy xuất từ TCBS
[2025-01-09T16:31:15.038+0000] {data_explorer.py:64} WARNING - Thông tin niêm yết & giao dịch sẽ được truy xuất từ TCBS
[2025-01-09T16:32:15.447+0000] {data_explorer.py:64} WARNING - Thông tin niêm yết & giao dịch sẽ được truy xuất từ TCBS
[2025-01-09T16:33:15.915+0000] {data_explorer.py:64} WARNING - Thông tin niêm yết & giao dịch sẽ được truy xuất từ TCBS
[2025-01-09T16:34:16.386+0000] {data_explorer.py:64} WARNING - Thông tin niêm yết & giao dịch sẽ được truy xuất từ TCBS
[2025-01-09T16:35:16.837+0000] {data_explorer.py:64} WARNING - Thông tin niêm yết & giao dịch sẽ được truy xuất từ TCBS
[2025-01-09T16:36:17.226+0000] {data_explorer.py:64} WARNING - Thông tin niêm yết & giao dịch sẽ được truy xuất từ TCBS
[2025-01-09T16:37:18.848+0000] {data_explorer.py:64} WARNING - Thông tin niêm yết & giao dịch sẽ được truy xuất từ TCBS
[2025-01-09T16:38:19.160+0000] {data_explorer.py:64} WARNING - Thông tin niêm yết & giao dịch sẽ được truy xuất từ TCBS
[2025-01-09T16:40:32.034+0000] {taskinstance.py:3311} ERROR - Task failed with exception
Traceback (most recent call last):
  File "/home/airflow/.local/lib/python3.11/site-packages/urllib3/connection.py", line 199, in _new_conn
    sock = connection.create_connection(
           ^^^^^^^^^^^^^^^^^^^^^^^^^^^^^
  File "/home/airflow/.local/lib/python3.11/site-packages/urllib3/util/connection.py", line 60, in create_connection
    for res in socket.getaddrinfo(host, port, family, socket.SOCK_STREAM):
               ^^^^^^^^^^^^^^^^^^^^^^^^^^^^^^^^^^^^^^^^^^^^^^^^^^^^^^^^^^
  File "/usr/local/lib/python3.11/socket.py", line 974, in getaddrinfo
    for res in _socket.getaddrinfo(host, port, family, type, proto, flags):
               ^^^^^^^^^^^^^^^^^^^^^^^^^^^^^^^^^^^^^^^^^^^^^^^^^^^^^^^^^^^
socket.gaierror: [Errno -2] Name or service not known

The above exception was the direct cause of the following exception:

Traceback (most recent call last):
  File "/home/airflow/.local/lib/python3.11/site-packages/urllib3/connectionpool.py", line 789, in urlopen
    response = self._make_request(
               ^^^^^^^^^^^^^^^^^^^
  File "/home/airflow/.local/lib/python3.11/site-packages/urllib3/connectionpool.py", line 490, in _make_request
    raise new_e
  File "/home/airflow/.local/lib/python3.11/site-packages/urllib3/connectionpool.py", line 466, in _make_request
    self._validate_conn(conn)
  File "/home/airflow/.local/lib/python3.11/site-packages/urllib3/connectionpool.py", line 1095, in _validate_conn
    conn.connect()
  File "/home/airflow/.local/lib/python3.11/site-packages/urllib3/connection.py", line 693, in connect
    self.sock = sock = self._new_conn()
                       ^^^^^^^^^^^^^^^^
  File "/home/airflow/.local/lib/python3.11/site-packages/urllib3/connection.py", line 206, in _new_conn
    raise NameResolutionError(self.host, self, e) from e
urllib3.exceptions.NameResolutionError: <urllib3.connection.HTTPSConnection object at 0x7fadbf1b5bd0>: Failed to resolve 'api.vietcap.com.vn' ([Errno -2] Name or service not known)

The above exception was the direct cause of the following exception:

Traceback (most recent call last):
  File "/home/airflow/.local/lib/python3.11/site-packages/requests/adapters.py", line 667, in send
    resp = conn.urlopen(
           ^^^^^^^^^^^^^
  File "/home/airflow/.local/lib/python3.11/site-packages/urllib3/connectionpool.py", line 843, in urlopen
    retries = retries.increment(
              ^^^^^^^^^^^^^^^^^^
  File "/home/airflow/.local/lib/python3.11/site-packages/urllib3/util/retry.py", line 519, in increment
    raise MaxRetryError(_pool, url, reason) from reason  # type: ignore[arg-type]
    ^^^^^^^^^^^^^^^^^^^^^^^^^^^^^^^^^^^^^^^^^^^^^^^^^^^
urllib3.exceptions.MaxRetryError: HTTPSConnectionPool(host='api.vietcap.com.vn', port=443): Max retries exceeded with url: /data-mt/graphql (Caused by NameResolutionError("<urllib3.connection.HTTPSConnection object at 0x7fadbf1b5bd0>: Failed to resolve 'api.vietcap.com.vn' ([Errno -2] Name or service not known)"))

During handling of the above exception, another exception occurred:

Traceback (most recent call last):
  File "/opt/airflow/dags/vnstock_stream.py", line 49, in get_current_price
    try:
         
  File "/opt/airflow/dags/vnstock_stream.py", line 60, in get_price_board
  File "/home/airflow/.local/lib/python3.11/site-packages/vnstock3/common/vnstock.py", line 46, in stock
    return StockComponents(self.symbol, source, show_log=self.show_log)
           ^^^^^^^^^^^^^^^^^^^^^^^^^^^^^^^^^^^^^^^^^^^^^^^^^^^^^^^^^^^^
  File "/home/airflow/.local/lib/python3.11/site-packages/vnstock3/common/data/data_explorer.py", line 38, in __init__
    self._initialize_components()
  File "/home/airflow/.local/lib/python3.11/site-packages/vnstock3/common/data/data_explorer.py", line 62, in _initialize_components
    self.finance = Finance(self.symbol, source=self.source)
                   ^^^^^^^^^^^^^^^^^^^^^^^^^^^^^^^^^^^^^^^^
  File "/home/airflow/.local/lib/python3.11/site-packages/vnstock3/common/data/data_explorer.py", line 359, in __init__
    self.data_source = self._load_data_source()
                       ^^^^^^^^^^^^^^^^^^^^^^^^
  File "/home/airflow/.local/lib/python3.11/site-packages/vnstock3/common/data/data_explorer.py", line 366, in _load_data_source
    return module.Finance(self.symbol)
           ^^^^^^^^^^^^^^^^^^^^^^^^^^^
  File "/home/airflow/.local/lib/python3.11/site-packages/vnstock3/explorer/vci/financial.py", line 39, in __init__
    self.com_type_code = self._get_company_type()
                         ^^^^^^^^^^^^^^^^^^^^^^^^
  File "/home/airflow/.local/lib/python3.11/site-packages/vnstock3/explorer/vci/financial.py", line 53, in _get_company_type
    listing_info = Company(symbol=self.symbol)._fetch_data()['CompanyListingInfo']
                   ^^^^^^^^^^^^^^^^^^^^^^^^^^^^^^^^^^^^^^^^^
  File "/home/airflow/.local/lib/python3.11/site-packages/vnstock3/explorer/vci/company.py", line 46, in _fetch_data
    response = requests.request("POST", url, headers=self.headers, data=payload)
               ^^^^^^^^^^^^^^^^^^^^^^^^^^^^^^^^^^^^^^^^^^^^^^^^^^^^^^^^^^^^^^^^^
  File "/home/airflow/.local/lib/python3.11/site-packages/requests/api.py", line 59, in request
    return session.request(method=method, url=url, **kwargs)
           ^^^^^^^^^^^^^^^^^^^^^^^^^^^^^^^^^^^^^^^^^^^^^^^^^
  File "/home/airflow/.local/lib/python3.11/site-packages/requests/sessions.py", line 589, in request
    resp = self.send(prep, **send_kwargs)
           ^^^^^^^^^^^^^^^^^^^^^^^^^^^^^^
  File "/home/airflow/.local/lib/python3.11/site-packages/requests/sessions.py", line 703, in send
    r = adapter.send(request, **kwargs)
        ^^^^^^^^^^^^^^^^^^^^^^^^^^^^^^^
  File "/home/airflow/.local/lib/python3.11/site-packages/requests/adapters.py", line 700, in send
    raise ConnectionError(e, request=request)
requests.exceptions.ConnectionError: HTTPSConnectionPool(host='api.vietcap.com.vn', port=443): Max retries exceeded with url: /data-mt/graphql (Caused by NameResolutionError("<urllib3.connection.HTTPSConnection object at 0x7fadbf1b5bd0>: Failed to resolve 'api.vietcap.com.vn' ([Errno -2] Name or service not known)"))

During handling of the above exception, another exception occurred:

Traceback (most recent call last):
  File "/home/airflow/.local/lib/python3.11/site-packages/airflow/models/taskinstance.py", line 767, in _execute_task
    result = _execute_callable(context=context, **execute_callable_kwargs)
             ^^^^^^^^^^^^^^^^^^^^^^^^^^^^^^^^^^^^^^^^^^^^^^^^^^^^^^^^^^^^^
  File "/home/airflow/.local/lib/python3.11/site-packages/airflow/models/taskinstance.py", line 733, in _execute_callable
    return ExecutionCallableRunner(
           ^^^^^^^^^^^^^^^^^^^^^^^^
  File "/home/airflow/.local/lib/python3.11/site-packages/airflow/utils/operator_helpers.py", line 252, in run
    return self.func(*args, **kwargs)
           ^^^^^^^^^^^^^^^^^^^^^^^^^^
  File "/home/airflow/.local/lib/python3.11/site-packages/airflow/models/baseoperator.py", line 417, in wrapper
    return func(self, *args, **kwargs)
           ^^^^^^^^^^^^^^^^^^^^^^^^^^^
  File "/home/airflow/.local/lib/python3.11/site-packages/airflow/operators/python.py", line 238, in execute
    return_value = self.execute_callable()
                   ^^^^^^^^^^^^^^^^^^^^^^^
  File "/home/airflow/.local/lib/python3.11/site-packages/airflow/operators/python.py", line 256, in execute_callable
    return runner.run(*self.op_args, **self.op_kwargs)
           ^^^^^^^^^^^^^^^^^^^^^^^^^^^^^^^^^^^^^^^^^^^
  File "/home/airflow/.local/lib/python3.11/site-packages/airflow/utils/operator_helpers.py", line 252, in run
    return self.func(*args, **kwargs)
           ^^^^^^^^^^^^^^^^^^^^^^^^^^
  File "/opt/airflow/dags/vnstock_stream.py", line 51, in get_current_price
    except Exception as e :
                ^^^^^^^^^^^^
  File "/opt/airflow/dags/vnstock_stream.py", line 35, in error_log_save
    f.write(time() + ' :' + err)
            ~~~~~~~^~~~~~
TypeError: unsupported operand type(s) for +: 'float' and 'str'
[2025-01-09T16:40:32.079+0000] {taskinstance.py:1225} INFO - Marking task as FAILED. dag_id=stock_information, task_id=stream_data_from_api, run_id=scheduled__2025-01-09T16:00:00+00:00, execution_date=20250109T160000, start_date=20250109T160102, end_date=20250109T164032
[2025-01-09T16:40:32.380+0000] {taskinstance.py:340} INFO - ::group::Post task execution logs
[2025-01-09T16:40:32.384+0000] {standard_task_runner.py:124} ERROR - Failed to execute job 48 for task stream_data_from_api (unsupported operand type(s) for +: 'float' and 'str'; 460)
Traceback (most recent call last):
  File "/home/airflow/.local/lib/python3.11/site-packages/urllib3/connection.py", line 199, in _new_conn
    sock = connection.create_connection(
           ^^^^^^^^^^^^^^^^^^^^^^^^^^^^^
  File "/home/airflow/.local/lib/python3.11/site-packages/urllib3/util/connection.py", line 60, in create_connection
    for res in socket.getaddrinfo(host, port, family, socket.SOCK_STREAM):
               ^^^^^^^^^^^^^^^^^^^^^^^^^^^^^^^^^^^^^^^^^^^^^^^^^^^^^^^^^^
  File "/usr/local/lib/python3.11/socket.py", line 974, in getaddrinfo
    for res in _socket.getaddrinfo(host, port, family, type, proto, flags):
               ^^^^^^^^^^^^^^^^^^^^^^^^^^^^^^^^^^^^^^^^^^^^^^^^^^^^^^^^^^^
socket.gaierror: [Errno -2] Name or service not known

The above exception was the direct cause of the following exception:

Traceback (most recent call last):
  File "/home/airflow/.local/lib/python3.11/site-packages/urllib3/connectionpool.py", line 789, in urlopen
    response = self._make_request(
               ^^^^^^^^^^^^^^^^^^^
  File "/home/airflow/.local/lib/python3.11/site-packages/urllib3/connectionpool.py", line 490, in _make_request
    raise new_e
  File "/home/airflow/.local/lib/python3.11/site-packages/urllib3/connectionpool.py", line 466, in _make_request
    self._validate_conn(conn)
  File "/home/airflow/.local/lib/python3.11/site-packages/urllib3/connectionpool.py", line 1095, in _validate_conn
    conn.connect()
  File "/home/airflow/.local/lib/python3.11/site-packages/urllib3/connection.py", line 693, in connect
    self.sock = sock = self._new_conn()
                       ^^^^^^^^^^^^^^^^
  File "/home/airflow/.local/lib/python3.11/site-packages/urllib3/connection.py", line 206, in _new_conn
    raise NameResolutionError(self.host, self, e) from e
urllib3.exceptions.NameResolutionError: <urllib3.connection.HTTPSConnection object at 0x7fadbf1b5bd0>: Failed to resolve 'api.vietcap.com.vn' ([Errno -2] Name or service not known)

The above exception was the direct cause of the following exception:

Traceback (most recent call last):
  File "/home/airflow/.local/lib/python3.11/site-packages/requests/adapters.py", line 667, in send
    resp = conn.urlopen(
           ^^^^^^^^^^^^^
  File "/home/airflow/.local/lib/python3.11/site-packages/urllib3/connectionpool.py", line 843, in urlopen
    retries = retries.increment(
              ^^^^^^^^^^^^^^^^^^
  File "/home/airflow/.local/lib/python3.11/site-packages/urllib3/util/retry.py", line 519, in increment
    raise MaxRetryError(_pool, url, reason) from reason  # type: ignore[arg-type]
    ^^^^^^^^^^^^^^^^^^^^^^^^^^^^^^^^^^^^^^^^^^^^^^^^^^^
urllib3.exceptions.MaxRetryError: HTTPSConnectionPool(host='api.vietcap.com.vn', port=443): Max retries exceeded with url: /data-mt/graphql (Caused by NameResolutionError("<urllib3.connection.HTTPSConnection object at 0x7fadbf1b5bd0>: Failed to resolve 'api.vietcap.com.vn' ([Errno -2] Name or service not known)"))

During handling of the above exception, another exception occurred:

Traceback (most recent call last):
  File "/opt/airflow/dags/vnstock_stream.py", line 49, in get_current_price
    try:
         
  File "/opt/airflow/dags/vnstock_stream.py", line 60, in get_price_board
  File "/home/airflow/.local/lib/python3.11/site-packages/vnstock3/common/vnstock.py", line 46, in stock
    return StockComponents(self.symbol, source, show_log=self.show_log)
           ^^^^^^^^^^^^^^^^^^^^^^^^^^^^^^^^^^^^^^^^^^^^^^^^^^^^^^^^^^^^
  File "/home/airflow/.local/lib/python3.11/site-packages/vnstock3/common/data/data_explorer.py", line 38, in __init__
    self._initialize_components()
  File "/home/airflow/.local/lib/python3.11/site-packages/vnstock3/common/data/data_explorer.py", line 62, in _initialize_components
    self.finance = Finance(self.symbol, source=self.source)
                   ^^^^^^^^^^^^^^^^^^^^^^^^^^^^^^^^^^^^^^^^
  File "/home/airflow/.local/lib/python3.11/site-packages/vnstock3/common/data/data_explorer.py", line 359, in __init__
    self.data_source = self._load_data_source()
                       ^^^^^^^^^^^^^^^^^^^^^^^^
  File "/home/airflow/.local/lib/python3.11/site-packages/vnstock3/common/data/data_explorer.py", line 366, in _load_data_source
    return module.Finance(self.symbol)
           ^^^^^^^^^^^^^^^^^^^^^^^^^^^
  File "/home/airflow/.local/lib/python3.11/site-packages/vnstock3/explorer/vci/financial.py", line 39, in __init__
    self.com_type_code = self._get_company_type()
                         ^^^^^^^^^^^^^^^^^^^^^^^^
  File "/home/airflow/.local/lib/python3.11/site-packages/vnstock3/explorer/vci/financial.py", line 53, in _get_company_type
    listing_info = Company(symbol=self.symbol)._fetch_data()['CompanyListingInfo']
                   ^^^^^^^^^^^^^^^^^^^^^^^^^^^^^^^^^^^^^^^^^
  File "/home/airflow/.local/lib/python3.11/site-packages/vnstock3/explorer/vci/company.py", line 46, in _fetch_data
    response = requests.request("POST", url, headers=self.headers, data=payload)
               ^^^^^^^^^^^^^^^^^^^^^^^^^^^^^^^^^^^^^^^^^^^^^^^^^^^^^^^^^^^^^^^^^
  File "/home/airflow/.local/lib/python3.11/site-packages/requests/api.py", line 59, in request
    return session.request(method=method, url=url, **kwargs)
           ^^^^^^^^^^^^^^^^^^^^^^^^^^^^^^^^^^^^^^^^^^^^^^^^^
  File "/home/airflow/.local/lib/python3.11/site-packages/requests/sessions.py", line 589, in request
    resp = self.send(prep, **send_kwargs)
           ^^^^^^^^^^^^^^^^^^^^^^^^^^^^^^
  File "/home/airflow/.local/lib/python3.11/site-packages/requests/sessions.py", line 703, in send
    r = adapter.send(request, **kwargs)
        ^^^^^^^^^^^^^^^^^^^^^^^^^^^^^^^
  File "/home/airflow/.local/lib/python3.11/site-packages/requests/adapters.py", line 700, in send
    raise ConnectionError(e, request=request)
requests.exceptions.ConnectionError: HTTPSConnectionPool(host='api.vietcap.com.vn', port=443): Max retries exceeded with url: /data-mt/graphql (Caused by NameResolutionError("<urllib3.connection.HTTPSConnection object at 0x7fadbf1b5bd0>: Failed to resolve 'api.vietcap.com.vn' ([Errno -2] Name or service not known)"))

During handling of the above exception, another exception occurred:

Traceback (most recent call last):
  File "/home/airflow/.local/lib/python3.11/site-packages/airflow/task/task_runner/standard_task_runner.py", line 117, in _start_by_fork
    ret = args.func(args, dag=self.dag)
          ^^^^^^^^^^^^^^^^^^^^^^^^^^^^^
  File "/home/airflow/.local/lib/python3.11/site-packages/airflow/cli/cli_config.py", line 49, in command
    return func(*args, **kwargs)
           ^^^^^^^^^^^^^^^^^^^^^
  File "/home/airflow/.local/lib/python3.11/site-packages/airflow/utils/cli.py", line 116, in wrapper
    return f(*args, **kwargs)
           ^^^^^^^^^^^^^^^^^^
  File "/home/airflow/.local/lib/python3.11/site-packages/airflow/cli/commands/task_command.py", line 483, in task_run
    task_return_code = _run_task_by_selected_method(args, _dag, ti)
                       ^^^^^^^^^^^^^^^^^^^^^^^^^^^^^^^^^^^^^^^^^^^^
  File "/home/airflow/.local/lib/python3.11/site-packages/airflow/cli/commands/task_command.py", line 256, in _run_task_by_selected_method
    return _run_raw_task(args, ti)
           ^^^^^^^^^^^^^^^^^^^^^^^
  File "/home/airflow/.local/lib/python3.11/site-packages/airflow/cli/commands/task_command.py", line 341, in _run_raw_task
    return ti._run_raw_task(
           ^^^^^^^^^^^^^^^^^
  File "/home/airflow/.local/lib/python3.11/site-packages/airflow/utils/session.py", line 97, in wrapper
    return func(*args, session=session, **kwargs)
           ^^^^^^^^^^^^^^^^^^^^^^^^^^^^^^^^^^^^^^
  File "/home/airflow/.local/lib/python3.11/site-packages/airflow/models/taskinstance.py", line 3005, in _run_raw_task
    return _run_raw_task(
           ^^^^^^^^^^^^^^
  File "/home/airflow/.local/lib/python3.11/site-packages/airflow/models/taskinstance.py", line 273, in _run_raw_task
    TaskInstance._execute_task_with_callbacks(
  File "/home/airflow/.local/lib/python3.11/site-packages/airflow/models/taskinstance.py", line 3159, in _execute_task_with_callbacks
    result = self._execute_task(context, task_orig)
             ^^^^^^^^^^^^^^^^^^^^^^^^^^^^^^^^^^^^^^
  File "/home/airflow/.local/lib/python3.11/site-packages/airflow/models/taskinstance.py", line 3183, in _execute_task
    return _execute_task(self, context, task_orig)
           ^^^^^^^^^^^^^^^^^^^^^^^^^^^^^^^^^^^^^^^
  File "/home/airflow/.local/lib/python3.11/site-packages/airflow/models/taskinstance.py", line 767, in _execute_task
    result = _execute_callable(context=context, **execute_callable_kwargs)
             ^^^^^^^^^^^^^^^^^^^^^^^^^^^^^^^^^^^^^^^^^^^^^^^^^^^^^^^^^^^^^
  File "/home/airflow/.local/lib/python3.11/site-packages/airflow/models/taskinstance.py", line 733, in _execute_callable
    return ExecutionCallableRunner(
           ^^^^^^^^^^^^^^^^^^^^^^^^
  File "/home/airflow/.local/lib/python3.11/site-packages/airflow/utils/operator_helpers.py", line 252, in run
    return self.func(*args, **kwargs)
           ^^^^^^^^^^^^^^^^^^^^^^^^^^
  File "/home/airflow/.local/lib/python3.11/site-packages/airflow/models/baseoperator.py", line 417, in wrapper
    return func(self, *args, **kwargs)
           ^^^^^^^^^^^^^^^^^^^^^^^^^^^
  File "/home/airflow/.local/lib/python3.11/site-packages/airflow/operators/python.py", line 238, in execute
    return_value = self.execute_callable()
                   ^^^^^^^^^^^^^^^^^^^^^^^
  File "/home/airflow/.local/lib/python3.11/site-packages/airflow/operators/python.py", line 256, in execute_callable
    return runner.run(*self.op_args, **self.op_kwargs)
           ^^^^^^^^^^^^^^^^^^^^^^^^^^^^^^^^^^^^^^^^^^^
  File "/home/airflow/.local/lib/python3.11/site-packages/airflow/utils/operator_helpers.py", line 252, in run
    return self.func(*args, **kwargs)
           ^^^^^^^^^^^^^^^^^^^^^^^^^^
  File "/opt/airflow/dags/vnstock_stream.py", line 51, in get_current_price
    except Exception as e :
                ^^^^^^^^^^^^
  File "/opt/airflow/dags/vnstock_stream.py", line 35, in error_log_save
    f.write(time() + ' :' + err)
            ~~~~~~~^~~~~~
TypeError: unsupported operand type(s) for +: 'float' and 'str'
[2025-01-09T16:40:32.453+0000] {local_task_job_runner.py:266} INFO - Task exited with return code 1
[2025-01-09T16:40:32.535+0000] {taskinstance.py:3895} INFO - 0 downstream tasks scheduled from follow-on schedule check
[2025-01-09T16:40:32.545+0000] {local_task_job_runner.py:245} INFO - ::endgroup::
